Workbook

Sheet Instrucciones
A1: Libro de trabajo de la AE2 · Proyecto Final de Grado 2026
A2: Universidad de la Cuenca del Plata · Ingeniería en Sistemas de Información · Comisión A · Sede Posadas · Docente Titular: PosDr. Darío Ezequiel Díaz · ISI-PFG-2026C2-AE2-v02
A4: Para qué sirve este libro | B4: Reúne, en un solo archivo versionable, los instrumentos de la Unidad Dos que producen el Capítulo III y alimentan los Capítulos V y X: el catálogo de requisitos, la matriz de trazabilidad, el filtro de entidades, el registro de reglas, el glosario, el plan de iteraciones y el dimensionamiento de recursos. La hoja «Panel» controla sola el estado de completitud y avisa qué falta.
A5: Dónde se guarda | B5: En el repositorio del equipo, carpeta /03-requisitos, con la nomenclatura de la cátedra: AAAAMMDD_CatalogoRequisitos_Equipo_vN.xlsx. Se versiona cada vez que se cierra un bloque de filas, no una sola vez antes de la entrega.
A6: Qué celdas se completan | B6: Todas las celdas blancas y grises de cada hoja, a partir de la fila 5. Las filas sombreadas en ocre son ejemplos resueltos sobre el caso conductor «Santa Ana»: se leen, no se copian, y se borran antes de entregar. Las columnas de control, sombreadas en amarillo, contienen fórmulas: no se escriben.
A7: Cómo se usan las listas desplegables | B7: Las columnas de tipo, prioridad y estado admiten sólo los valores de la lista. Si un valor es rechazado, es porque la categoría no corresponde a la clasificación de la cátedra.
A8: Qué mira la corrección | B8: Que cada requisito tenga sus seis campos, que su criterio de aceptación sea un procedimiento ejecutable por un tercero, que la trazabilidad cierre en doble vía y que el conjunto de los requisitos «Must» coincida con el producto mínimo viable del apartado V.5.
A9: Orden de trabajo sugerido | B9: 1) Entidades y Reglas, en el taller. 2) Trazabilidad, con los hallazgos de la AE1 codificados H-01, H-02… 3) Catálogo, derivando requisitos de esos hallazgos. 4) Sesión de validación con el referente y actualización de los estados. 5) Iteraciones y Recursos, ya con el catálogo cerrado.
A10: Advertencia | B10: Ante divergencia entre este libro y la Consigna ISI-PFG-2026C2-AE2-v02, prevalece la consigna. Ante divergencia entre la consigna y la Resolución Rectoral UCP N.º 97/23, prevalece la Resolución.
A12: Leyenda de colores
A13: Ocre | B13: Fila de ejemplo resuelta sobre el caso «Santa Ana». Se borra antes de entregar.
A14: Amarillo | B14: Celda con fórmula de control. No se escribe.
A15: Blanco y gris | B15: Celdas que completa el equipo.
A17: Versión | B17: Versión 3 del 05/10/2026 (borrador de la Ventana de Mejora). La versión 2 es la entregada el 02/10/2026 a las 21:42. Se borraron las filas de ejemplo.
A18: Hojas agregadas | B18: «Equivalencias» (qué pasó con los códigos de hallazgo de la versión 2) y, en «Iteraciones», la tabla de horas por requisito y perfil, que alimenta las horas asignadas y el Capítulo X.

Sheet Catálogo
A1: Catálogo de requisitos · apartado III.5 del informe
A2: Una fila por requisito, con los seis campos completos. Regla de cómputo: un requisito sin criterio de aceptación comprobable no se computa, por bien redactado que esté. Antes de cerrar una fila, aplique la prueba del compañero: otro integrante debe poder decir, en diez segundos, cómo verificaría el requisito.
A4: ID | B4: Enunciado | C4: Tipo | D4: Categoría (si es no funcional) | E4: Prioridad | F4: Motivo de la prioridad | G4: Criterio de aceptación (condición, acción, resultado con valores) | H4: Trazabilidad (H-xx o acta) | I4: Estado de validación | J4: Iteración prevista | K4: ¿Integra el MVP? | L4: Control de completitud
A5: RF-01 | B5: El sistema muestra en una grilla el estado actual de las 13 habitaciones. | C5: Funcional | E5: Must | F5: Sustituye el tablero de madera y los papeles anotadores como única vista del estado de las habitaciones. | G5: Condición inicial: la tabla habitaciones tiene 13 filas. Acción: cargar la vista principal en un navegador a 1366 × 768 px. Resultado: se muestran 13 tarjetas, una por fila de la tabla, con el estado en color (Libre = verde, Ocupada = azul, En Limpieza = amarillo, Mantenimiento = gris) y la grilla carga en menos de 500 ms (percentil 95 de 5 cargas). | H5: H-01, H-05, H-15 · Acta 23/09 | I5: Validado | J5: 2 | K5: Sí | L5: =IF($A5="","",IF(COUNTBLANK($B5:$C5)+COUNTBLANK($E5:$H5)>0,"Faltan campos",IF(AND($C5="No funcional",$D5=""),"Falta categoría",IF($K5="","Falta definir si integra el MVP","Fila completa")))) -> Fila completa
A6: RF-02 | B6: El sistema registra el inicio de un turno sobre una habitación libre con la hora de ingreso fijada por el servidor. | C6: Funcional | E6: Must | F6: Es el núcleo transaccional del servicio por hora; elimina la hora de ingreso escrita o alterada a mano. | G6: Condición inicial: habitación 01 en estado Libre y una tarifa vigente. Acción: el conserje confirma la apertura, con la patente AE987CD opcional. Resultado: se crea el turno En Curso con hora_inicio asignada por el servidor y la tarifa_base copiada del momento, y la habitación pasa a Ocupada; una segunda apertura sobre la misma habitación responde 409 (RN-EXI-01). | H6: H-04, H-16 · Acta 23/09 | I6: Validado | J6: 2 | K6: Sí | L6: =IF($A6="","",IF(COUNTBLANK($B6:$C6)+COUNTBLANK($E6:$H6)>0,"Faltan campos",IF(AND($C6="No funcional",$D6=""),"Falta categoría",IF($K6="","Falta definir si integra el MVP","Fila completa")))) -> Fila completa
A7: RF-03 | B7: El sistema calcula el importe del turno con la tarifa base y el sobreturno por fracciones de 30 min. | C7: Funcional | E7: Must | F7: Automatiza la liquidación y elimina las sumas manuales de tiempos de estadía. | G7: Condición inicial: tarifa Estándar vigente ($8.000 por 120 min y $2.500 por cada fracción de 30 min o porción, sin tolerancia) y un turno En Curso. Acción: pedir el resumen del turno a los 120, 121, 150 y 151 min. Resultado: sobreturno de $0, $2.500, $2.500 y $5.000; total = tarifa base + sobreturno + consumos (RN-DER-01 y RN-DER-02). La gerencia aprueba los importes de la tarifa en el acta del 06/10/2026; el acta del 23/09 aprueba la regla. | H7: H-05, H-07, H-16 · Acta 23/09 | I7: Validado | J7: 2 | K7: Sí | L7: =IF($A7="","",IF(COUNTBLANK($B7:$C7)+COUNTBLANK($E7:$H7)>0,"Faltan campos",IF(AND($C7="No funcional",$D7=""),"Falta categoría",IF($K7="","Falta definir si integra el MVP","Fila completa")))) -> Fila completa
A8: RF-04 | B8: El sistema registra el consumo de minibar de un turno y descuenta el stock en la misma transacción. | C8: Funcional | E8: Must | F8: Reemplaza el conteo físico de lo consumido en cada arqueo y evita mermas no registradas. | G8: Condición inicial: turno En Curso y artículo MIN-001 con stock 10. Acción: despachar 2 unidades. Resultado: el stock queda en 8, se crea la línea de consumo con subtotal = 2 × precio unitario y el total del turno aumenta en ese subtotal, todo en una única transacción. | H8: H-05, H-16 · Acta 23/09 | I8: Validado | J8: 2 | K8: Sí | L8: =IF($A8="","",IF(COUNTBLANK($B8:$C8)+COUNTBLANK($E8:$H8)>0,"Faltan campos",IF(AND($C8="No funcional",$D8=""),"Falta categoría",IF($K8="","Falta definir si integra el MVP","Fila completa")))) -> Fila completa
A9: RF-05 | B9: El sistema rechaza el consumo de un artículo cuando la cantidad pedida supera el stock. | C9: Funcional | E9: Must | F9: Aplica RN-EXI-02 y evita stock negativo y consumos ficticios. | G9: Condición inicial: artículo con stock 0, o con stock menor a la cantidad pedida. Acción: despachar 1 unidad. Resultado: respuesta 400 con el mensaje «Stock insuficiente», sin línea de consumo y sin cambio en el stock ni en los totales del turno. | H9: H-05, H-16 · Acta 23/09 | I9: Validado | J9: 2 | K9: Sí | L9: =IF($A9="","",IF(COUNTBLANK($B9:$C9)+COUNTBLANK($E9:$H9)>0,"Faltan campos",IF(AND($C9="No funcional",$D9=""),"Falta categoría",IF($K9="","Falta definir si integra el MVP","Fila completa")))) -> Fila completa
A10: RF-06 | B10: El sistema registra el cobro desglosado por medio de pago, con el comprobante de los pagos electrónicos. | C10: Funcional | E10: Must | F10: Permite conciliar efectivo y comprobantes de POSNET en el arqueo, como hoy hace el conserje con sus anotadores. | G10: Condición inicial: turno En Curso con saldo adeudado de $X. Acción: confirmar el cobro con efectivo y POSNET cuyos importes suman exactamente $X, y el número de comprobante del POSNET. Resultado: un registro de pago por medio, la constancia de cobro y saldo $0; un pago electrónico sin comprobante responde 422 y un desglose que no suma $X responde 400. | H10: H-17, H-19 · Acta 23/09 | I10: Validado | J10: 2 | K10: Sí | L10: =IF($A10="","",IF(COUNTBLANK($B10:$C10)+COUNTBLANK($E10:$H10)>0,"Faltan campos",IF(AND($C10="No funcional",$D10=""),"Falta categoría",IF($K10="","Falta definir si integra el MVP","Fila completa")))) -> Fila completa
A11: RF-07 | B11: El sistema impide pasar a En Limpieza una habitación cuyo turno tiene saldo adeudado. | C11: Funcional | E11: Must | F11: Aplica RN-EXI-03: una habitación no se libera sin cobrar la totalidad del saldo. | G11: Condición inicial: turno En Curso con saldo adeudado mayor a $0. Acción: pedir el cambio de la habitación a En Limpieza. Resultado: respuesta 409 con el saldo adeudado, la habitación continúa Ocupada y el turno continúa En Curso. | H11: H-04, H-15 · Acta 23/09 | I11: Validado | J11: 2 | K11: Sí | L11: =IF($A11="","",IF(COUNTBLANK($B11:$C11)+COUNTBLANK($E11:$H11)>0,"Faltan campos",IF(AND($C11="No funcional",$D11=""),"Falta categoría",IF($K11="","Falta definir si integra el MVP","Fila completa")))) -> Fila completa
A12: RF-08 | B12: El sistema procesa el cierre de caja ciego al final de cada guardia de 8 h. | C12: Funcional | E12: Must | F12: Es el control directo sobre la discrepancia de caja: el conserje declara el efectivo y los comprobantes antes de conocer el total del sistema (RN-RES-03). | G12: Condición inicial: guardia terminada, con turnos cobrados y un operador saliente identificado. Acción: el operador ingresa el recuento físico de efectivo y de comprobantes. Resultado: antes de confirmar el recuento ninguna respuesta de la API incluye el total del sistema; al confirmar se guarda el arqueo con total declarado, total del sistema y diferencia, y el registro queda bloqueado contra UPDATE y DELETE. | H12: H-02, H-03, H-06, H-13, H-17, H-18, H-22 · Acta 23/09 | I12: Validado | J12: 3 | K12: Sí | L12: =IF($A12="","",IF(COUNTBLANK($B12:$C12)+COUNTBLANK($E12:$H12)>0,"Faltan campos",IF(AND($C12="No funcional",$D12=""),"Falta categoría",IF($K12="","Falta definir si integra el MVP","Fila completa")))) -> Fila completa
A13: RF-09 | B13: El sistema calcula y clasifica la diferencia entre lo declarado y lo registrado en cada arqueo. | C13: Funcional | E13: Must | F13: Entrega a la gerencia la métrica por guardia y por operador que hoy se obtiene a mano (H-18). | G13: Condición inicial: arqueo confirmado con total declarado D y total del sistema S. Acción: el sistema aplica RN-DER-03. Resultado: se guarda la diferencia D − S y su categoría: «Correcto» si es 0, «Faltante» si es negativa y «Sobrante» si es positiva; con D = $50.000 y S = $52.500 el resultado es Faltante de $2.500. | H13: H-03, H-06, H-18 · Acta 23/09 | I13: Validado | J13: 3 | K13: Sí | L13: =IF($A13="","",IF(COUNTBLANK($B13:$C13)+COUNTBLANK($E13:$H13)>0,"Faltan campos",IF(AND($C13="No funcional",$D13=""),"Falta categoría",IF($K13="","Falta definir si integra el MVP","Fila completa")))) -> Fila completa
A14: RF-10 | B14: El sistema genera un comprobante de arqueo en PDF. | C14: Funcional | E14: Should | F14: Da respaldo documental a la rendición y reduce la revisión manual de balances anteriores (H-23). | G14: Condición inicial: arqueo cerrado. Acción: exportar el comprobante. Resultado: se descarga un PDF con la guardia, el operador, los turnos, los importes por medio de pago, el total declarado, el total del sistema y la diferencia, en menos de 2 s con 50 turnos. | H14: H-23 · Acta 23/09 | I14: Validado | J14: 4 | K14: No | L14: =IF($A14="","",IF(COUNTBLANK($B14:$C14)+COUNTBLANK($E14:$H14)>0,"Faltan campos",IF(AND($C14="No funcional",$D14=""),"Falta categoría",IF($K14="","Falta definir si integra el MVP","Fila completa")))) -> Fila completa
A15: RF-11 | B15: El sistema permite al administrador modificar la tarifa vigente y los precios de los artículos. | C15: Funcional | E15: Should | F15: Las tarifas cambian con alta frecuencia (H-07) y no pueden estar fijas en el código. | G15: Condición inicial: sesión con rol Administrador y un turno finalizado con tarifa_base $8.000. Acción: cambiar la tarifa vigente a $9.000. Resultado: los turnos nuevos copian $9.000 y el turno finalizado conserva $8.000 y sus importes. | H15: H-07 · Acta 23/09 | I15: Validado | J15: 4 | K15: No | L15: =IF($A15="","",IF(COUNTBLANK($B15:$C15)+COUNTBLANK($E15:$H15)>0,"Faltan campos",IF(AND($C15="No funcional",$D15=""),"Falta categoría",IF($K15="","Falta definir si integra el MVP","Fila completa")))) -> Fila completa
A16: RF-12 | B16: El sistema marca en la grilla las habitaciones que superan 30 min en En Limpieza. | C16: Funcional | E16: Could | F16: La limpieza hoy no se anota (H-15) ni se mide (H-11); la marca hace visible la demora. | G16: Condición inicial: habitación en En Limpieza desde hace más de 30 min. Acción: refrescar la grilla. Resultado: la tarjeta muestra la marca «Demora de limpieza» con los minutos transcurridos; con 30 min o menos no se muestra. | H16: H-11, H-15 · Acta 23/09 | I16: Validado | J16: 4 | K16: No | L16: =IF($A16="","",IF(COUNTBLANK($B16:$C16)+COUNTBLANK($E16:$H16)>0,"Faltan campos",IF(AND($C16="No funcional",$D16=""),"Falta categoría",IF($K16="","Falta definir si integra el MVP","Fila completa")))) -> Fila completa
A17: RF-13 | B17: El sistema emite avisos sonoros en el navegador. | C17: Funcional | E17: Won't | F17: Queda fuera de este proyecto: el puesto de ventanilla no requiere avisos sonoros y la alerta visual de RF-12 cubre la necesidad. | G17: Condición inicial: se genera una alerta operativa (RF-12). Acción: cargar la interfaz. Resultado: la alerta se muestra solo en forma visual y el navegador no reproduce ningún sonido. | H17: Decisión de alcance (III.4), sin hallazgo · Acta 23/09 | I17: Validado | J17: No se planifica | K17: No | L17: =IF($A17="","",IF(COUNTBLANK($B17:$C17)+COUNTBLANK($E17:$H17)>0,"Faltan campos",IF(AND($C17="No funcional",$D17=""),"Falta categoría",IF($K17="","Falta definir si integra el MVP","Fila completa")))) -> Fila completa
A18: RNF-01 | B18: La base de datos rechaza toda modificación y todo borrado de un turno cerrado, de sus pagos y de sus consumos. | C18: No funcional | D18: Fiabilidad | E18: Must | F18: Impide que una sentencia de la aplicación altere lo ya cobrado (H-04, H-22). | G18: Condición inicial: turno FINALIZADO con un pago y un consumo en PostgreSQL 16. Acción: ejecutar UPDATE y DELETE desde SQL sobre el turno, sobre su pago y sobre su consumo. Resultado: el motor rechaza las seis sentencias con la excepción de RN-RES-01 (db/verify_inmutabilidad.sql, paso del canal). Alcance: sentencias de la aplicación; el dueño de las tablas puede deshabilitar un trigger, y esa brecha se cierra con el rol de aplicación motel_app, que no es dueño de las tablas (v1.2; db/verify_roles.sql, paso del canal). | H18: H-04, H-22, H-23 · Acta 23/09 | I18: Validado | J18: 2 | K18: Sí | L18: =IF($A18="","",IF(COUNTBLANK($B18:$C18)+COUNTBLANK($E18:$H18)>0,"Faltan campos",IF(AND($C18="No funcional",$D18=""),"Falta categoría",IF($K18="","Falta definir si integra el MVP","Fila completa")))) -> Fila completa
A19: RNF-02 | B19: El backend responde la apertura y el cobro de un turno en 800 ms o menos. | C19: No funcional | D19: Rendimiento | E19: Must | F19: El cobro debe resolverse en un paso, sin demorar al cliente en la salida (H-08). | G19: Condición inicial: API en el entorno de despliegue con 5 peticiones concurrentes de apertura y 5 de cobro. Acción: repetir 20 veces y medir la latencia. Resultado: el percentil 95 es de 800 ms o menos. La gerencia aprueba el umbral en el acta del 06/10/2026. | H19: H-02, H-08, H-14 · Acta 23/09 | I19: Validado | J19: 3 | K19: Sí | L19: =IF($A19="","",IF(COUNTBLANK($B19:$C19)+COUNTBLANK($E19:$H19)>0,"Faltan campos",IF(AND($C19="No funcional",$D19=""),"Falta categoría",IF($K19="","Falta definir si integra el MVP","Fila completa")))) -> Fila completa
A20: RNF-03 | B20: El sistema no almacena nombre, apellido, DNI, teléfono, correo ni domicilio del cliente. | C20: No funcional | D20: Cumplimiento normativo | E20: Must | F20: Minimización de datos: el negocio no necesita identificar al cliente y la Ley 25.326 (art. 4) pide datos adecuados, pertinentes y no excesivos. | G20: Condición inicial: esquema creado con db/init.sql. Acción: consultar information_schema.columns. Resultado: ninguna columna de ninguna tabla guarda nombre, apellido, DNI, teléfono, correo ni domicilio del cliente; el cliente se identifica solo por la patente (opcional) o por el tipo Peatón. La retención de la patente se trata en RNF-08. | H20: H-08, H-20 · Acta 23/09 | I20: Validado | J20: 2 | K20: Sí | L20: =IF($A20="","",IF(COUNTBLANK($B20:$C20)+COUNTBLANK($E20:$H20)>0,"Faltan campos",IF(AND($C20="No funcional",$D20=""),"Falta categoría",IF($K20="","Falta definir si integra el MVP","Fila completa")))) -> Fila completa
A21: RNF-04 | B21: El sistema identifica a cada operador y atribuye a su sesión los turnos, cobros y arqueos que ejecuta. | C21: No funcional | D21: Seguridad | E21: Must | F21: El cierre ciego necesita saber a quién atribuir un faltante (RF-09) y la AE1 exige delimitar responsabilidades (H-06). | G21: Condición inicial: dos conserjes con credenciales propias. Acción: un conserje inicia sesión y ejecuta una apertura y un cobro; desde la consola del navegador se ejecuta document.cookie. Resultado: el token JWT no es visible (cookie httpOnly), el turno y el pago registran el identificador de ese operador y una petición sin token responde 401. La gerencia aprueba el requisito en el acta del 06/10/2026; el mecanismo se decide en el prototipo v2. | H21: H-06, H-17 · Acta 23/09 | I21: Validado | J21: 3 | K21: Sí | L21: =IF($A21="","",IF(COUNTBLANK($B21:$C21)+COUNTBLANK($E21:$H21)>0,"Faltan campos",IF(AND($C21="No funcional",$D21=""),"Falta categoría",IF($K21="","Falta definir si integra el MVP","Fila completa")))) -> Fila completa
A22: RNF-05 | B22: La interfaz se usa sin desplazamiento horizontal en 1366 × 768 px y con controles de al menos 44 × 44 px. | C22: No funcional | D22: Usabilidad | E22: Must | F22: Debe operar en la terminal de la ventanilla. La gerencia aprueba el requisito en el acta del 06/10/2026 y el autor relevó en el local que ese monitor es de 1366 × 768 px. | G22: Condición inicial: navegador a 1366 × 768 px. Acción: recorrer apertura, consumo y cobro. Resultado: no aparece barra de desplazamiento horizontal y cada control tiene un área de clic de al menos 44 × 44 px, comprobada con las herramientas del navegador. | H22: Sin hallazgo: relevamiento del autor en el local (monitor de 1366 × 768 px) · Acta 23/09 | I22: Validado | J22: 2 | K22: Sí | L22: =IF($A22="","",IF(COUNTBLANK($B22:$C22)+COUNTBLANK($E22:$H22)>0,"Faltan campos",IF(AND($C22="No funcional",$D22=""),"Falta categoría",IF($K22="","Falta definir si integra el MVP","Fila completa")))) -> Fila completa
A23: RNF-06 | B23: El servicio tiene una disponibilidad mensual de 99,5 % o más. | C23: No funcional | D23: Fiabilidad | E23: Should | F23: El motel opera las 24 h y la región presenta intermitencias (H-09). | G23: Condición inicial: sondeo de /health cada 60 s durante 30 días en el entorno de despliegue. Acción: sumar los minutos sin respuesta. Resultado: 216 min o menos en 30 días (99,5 % de 43.200 min). | H23: H-09 · Acta 23/09 | I23: Validado | J23: 4 | K23: No | L23: =IF($A23="","",IF(COUNTBLANK($B23:$C23)+COUNTBLANK($E23:$H23)>0,"Faltan campos",IF(AND($C23="No funcional",$D23=""),"Falta categoría",IF($K23="","Falta definir si integra el MVP","Fila completa")))) -> Fila completa
A24: RNF-07 | B24: Los módulos de liquidación y de caja tienen una cobertura de pruebas de 70 % o más. | C24: No funcional | D24: Mantenibilidad | E24: Should | F24: Protege las reglas de cálculo frente a regresiones cuando cambian las tarifas. | G24: Condición inicial: canal de integración continua ejecutando pytest con medición de cobertura. Acción: medir la cobertura de los módulos de liquidación y de caja. Resultado: 70 % o más de líneas; el canal falla si baja de ese valor. | H24: Decisión de calidad del autor, sin hallazgo · Acta 23/09 | I24: Validado | J24: 3 | K24: No | L24: =IF($A24="","",IF(COUNTBLANK($B24:$C24)+COUNTBLANK($E24:$H24)>0,"Faltan campos",IF(AND($C24="No funcional",$D24=""),"Falta categoría",IF($K24="","Falta definir si integra el MVP","Fila completa")))) -> Fila completa
A25: RNF-08 | B25: La patente de un turno se elimina dentro de las 24 h posteriores a su cierre. | C25: No funcional | D25: Cumplimiento normativo | E25: Must | F25: La patente identifica de forma indirecta al titular del vehículo; se conserva mientras el vehículo está en el motel y luego se elimina (Ley 25.326, art. 4, inc. 7). La gerencia aprueba las 24 h en el acta del 06/10/2026, declara que necesita la patente por razones de seguridad e informa que no hay indicación del asesor legal. | G25: Condición inicial: turno FINALIZADO con patente AE987CD, cerrado hace más de 24 h. Acción: ejecutar la depuración y consultar los turnos cerrados y la tabla de estadía activa. Resultado: ninguna patente de un turno cerrado hace más de 24 h permanece almacenada (la consulta devuelve 0 filas) y los importes del turno quedan intactos, sin deshabilitar los triggers de inmutabilidad. | H25: H-08, H-16, H-20 · Acta 23/09 | I25: Validado | J25: 3 | K25: Sí | L25: =IF($A25="","",IF(COUNTBLANK($B25:$C25)+COUNTBLANK($E25:$H25)>0,"Faltan campos",IF(AND($C25="No funcional",$D25=""),"Falta categoría",IF($K25="","Falta definir si integra el MVP","Fila completa")))) -> Fila completa
A26: RNF-09 | B26: Ante una pérdida de conexión del navegador, los cronómetros de los turnos continúan en el servidor y la interfaz recupera el estado en 5 s o menos al reconectar. | C26: No funcional | D26: Fiabilidad | E26: Should | F26: Es la decisión de la AE1 para las intermitencias de internet (H-09); reemplaza la idea de persistencia local en caché, que no se sostiene con el servidor en la nube. | G26: Condición inicial: tres turnos En Curso. Acción: cortar la conexión del navegador durante 10 min y restablecerla. Resultado: en 5 s o menos la grilla muestra los tres turnos con los minutos calculados por el servidor (diferencia de 1 min o menos respecto de su reloj), sin turnos perdidos ni duplicados. Durante el corte no se pueden abrir ni cobrar turnos; el procedimiento de contingencia manual no se define en la sesión del 06/10/2026; el autor propone anotar los turnos en papel y cargarlos al volver la conexión. | H26: H-09 · Acta 23/09 | I26: Validado | J26: 4 | K26: No | L26: =IF($A26="","",IF(COUNTBLANK($B26:$C26)+COUNTBLANK($E26:$H26)>0,"Faltan campos",IF(AND($C26="No funcional",$D26=""),"Falta categoría",IF($K26="","Falta definir si integra el MVP","Fila completa")))) -> Fila completa
A27: RF-14 | B27: El sistema permite a la gerencia cerrar, sin ver el total, la caja que un conserje dejó abierta, con un motivo obligatorio y registrando quién la cerró. | C27: Funcional | E27: Should | F27: Con un solo responsable por guardia, una caja que queda abierta bloquea la ventanilla para la guardia siguiente; el cierre por la gerencia la libera sin perder el control ciego. | G27: Condición inicial: guardia abierta del conserje A con un cobro de $8.000 en efectivo y un fondo de cambio de $25.000. Acción: la gerencia declara $32.000 en efectivo y el motivo «el conserje se retiró sin cerrar». Resultado: antes de confirmar ninguna respuesta incluye el total del sistema; se guarda el arqueo en la caja de A con una diferencia de −$1.000 (Faltante), confirmado por la gerencia y con el motivo; sin motivo responde 422 y un conserje que lo intente responde 403. | H27: H-13, H-17 · Acta 19/10 | I27: Validado | J27: 3 | K27: No | L27: =IF($A27="","",IF(COUNTBLANK($B27:$C27)+COUNTBLANK($E27:$H27)>0,"Faltan campos",IF(AND($C27="No funcional",$D27=""),"Falta categoría",IF($K27="","Falta definir si integra el MVP","Fila completa")))) -> Fila completa
L28: =IF($A28="","",IF(COUNTBLANK($B28:$C28)+COUNTBLANK($E28:$H28)>0,"Faltan campos",IF(AND($C28="No funcional",$D28=""),"Falta categoría",IF($K28="","Falta definir si integra el MVP","Fila completa"))))
L29: =IF($A29="","",IF(COUNTBLANK($B29:$C29)+COUNTBLANK($E29:$H29)>0,"Faltan campos",IF(AND($C29="No funcional",$D29=""),"Falta categoría",IF($K29="","Falta definir si integra el MVP","Fila completa"))))
L30: =IF($A30="","",IF(COUNTBLANK($B30:$C30)+COUNTBLANK($E30:$H30)>0,"Faltan campos",IF(AND($C30="No funcional",$D30=""),"Falta categoría",IF($K30="","Falta definir si integra el MVP","Fila completa"))))
L31: =IF($A31="","",IF(COUNTBLANK($B31:$C31)+COUNTBLANK($E31:$H31)>0,"Faltan campos",IF(AND($C31="No funcional",$D31=""),"Falta categoría",IF($K31="","Falta definir si integra el MVP","Fila completa"))))
L32: =IF($A32="","",IF(COUNTBLANK($B32:$C32)+COUNTBLANK($E32:$H32)>0,"Faltan campos",IF(AND($C32="No funcional",$D32=""),"Falta categoría",IF($K32="","Falta definir si integra el MVP","Fila completa"))))
L33: =IF($A33="","",IF(COUNTBLANK($B33:$C33)+COUNTBLANK($E33:$H33)>0,"Faltan campos",IF(AND($C33="No funcional",$D33=""),"Falta categoría",IF($K33="","Falta definir si integra el MVP","Fila completa"))))
L34: =IF($A34="","",IF(COUNTBLANK($B34:$C34)+COUNTBLANK($E34:$H34)>0,"Faltan campos",IF(AND($C34="No funcional",$D34=""),"Falta categoría",IF($K34="","Falta definir si integra el MVP","Fila completa"))))
L35: =IF($A35="","",IF(COUNTBLANK($B35:$C35)+COUNTBLANK($E35:$H35)>0,"Faltan campos",IF(AND($C35="No funcional",$D35=""),"Falta categoría",IF($K35="","Falta definir si integra el MVP","Fila completa"))))
L36: =IF($A36="","",IF(COUNTBLANK($B36:$C36)+COUNTBLANK($E36:$H36)>0,"Faltan campos",IF(AND($C36="No funcional",$D36=""),"Falta categoría",IF($K36="","Falta definir si integra el MVP","Fila completa"))))
L37: =IF($A37="","",IF(COUNTBLANK($B37:$C37)+COUNTBLANK($E37:$H37)>0,"Faltan campos",IF(AND($C37="No funcional",$D37=""),"Falta categoría",IF($K37="","Falta definir si integra el MVP","Fila completa"))))
L38: =IF($A38="","",IF(COUNTBLANK($B38:$C38)+COUNTBLANK($E38:$H38)>0,"Faltan campos",IF(AND($C38="No funcional",$D38=""),"Falta categoría",IF($K38="","Falta definir si integra el MVP","Fila completa"))))
L39: =IF($A39="","",IF(COUNTBLANK($B39:$C39)+COUNTBLANK($E39:$H39)>0,"Faltan campos",IF(AND($C39="No funcional",$D39=""),"Falta categoría",IF($K39="","Falta definir si integra el MVP","Fila completa"))))
... L201: =IF($A201="","",IF(COUNTBLANK($B201:$C201)+COUNTBLANK($E201:$H201)>0,"Faltan campos",IF(AND($C201="No funcional",$D201=""),"Falta categoría",IF($K201="","Falta definir si integra el MVP","Fila completa"))))

Sheet Trazabilidad
A1: Matriz de trazabilidad · hallazgo de la AE1 → requisito
A2: Se verifica en doble vía. Todo requisito llega a un hallazgo; todo hallazgo llega a un requisito o a una justificación expresa de por qué no derivó ninguno. El silencio no es una decisión.
A4: Código (H-01, H-02…) | B4: Hallazgo de la AE1 (dato y valor) | C4: Fuente (apartado del Cap. II o acta) | D4: Requisito(s) derivado(s) | E4: Si no deriva: justificación | F4: Control de la doble vía
A5: H-01 | B5: 13 habitaciones, 3 guardias diarias y unos 30 turnos por día hábil (lunes a jueves) y unos 40 en fin de semana (viernes a domingo). La AE1 original informa 20 a 30 y 40 a 50; rige lo que la gerencia dice en la entrevista. | C5: AE1 · II.3 (v2) y entrevista, pág. 1 | D5: RF-01 | F5: =IF($A5="","",IF(AND($D5="",$E5=""),"Hallazgo sin destino",IF($D5="","Sin requisito, justificado","Deriva requisito"))) -> Deriva requisito
A6: H-02 | B6: El arqueo manual de cada recambio de guardia demora 17 min en promedio (cronometrado: 16, 18 y 17 min). | C6: AE1 · II.3 y Anexo I | D6: RF-08, RNF-02 | F6: =IF($A6="","",IF(AND($D6="",$E6=""),"Hallazgo sin destino",IF($D6="","Sin requisito, justificado","Deriva requisito"))) -> Deriva requisito
A7: H-03 | B7: Tasa de Discrepancia de Caja (TDC): 1 de cada 10 recambios (10 %) presenta faltante o sobrante de efectivo. | C7: AE1 · II.3, II.4 (Figura 1) | D7: RF-08, RF-09 | F7: =IF($A7="","",IF(AND($D7="",$E7=""),"Hallazgo sin destino",IF($D7="","Sin requisito, justificado","Deriva requisito"))) -> Deriva requisito
A8: H-04 | B8: Hallazgo 1: el soporte en papel permite anular un turno físicamente y sin rastro; la TDC no se explica solo por errores aritméticos. | C8: AE1 · II.6 | D8: RF-02, RF-07, RNF-01 | F8: =IF($A8="","",IF(AND($D8="",$E8=""),"Hallazgo sin destino",IF($D8="","Sin requisito, justificado","Deriva requisito"))) -> Deriva requisito
A9: H-05 | B9: Hallazgo 2: el arqueo consume sus 17 min en reconstruir a mano la línea de tiempo de cada habitación y en contar los productos consumidos. | C9: AE1 · II.6 | D9: RF-01, RF-03, RF-04, RF-05 | F9: =IF($A9="","",IF(AND($D9="",$E9=""),"Hallazgo sin destino",IF($D9="","Sin requisito, justificado","Deriva requisito"))) -> Deriva requisito
A10: H-06 | B10: El conserje no debe ver el total calculado antes de declarar el efectivo físico, para delimitar su responsabilidad ante faltantes. | C10: AE1 · II.5 (político y legal) | D10: RF-08, RF-09, RNF-04 | F10: =IF($A10="","",IF(AND($D10="",$E10=""),"Hallazgo sin destino",IF($D10="","Sin requisito, justificado","Deriva requisito"))) -> Deriva requisito
A11: H-07 | B11: Las tarifas por turno y por sobreturno se ajustan con alta frecuencia por la inflación. | C11: AE1 · II.5 (económico) | D11: RF-03, RF-11 | F11: =IF($A11="","",IF(AND($D11="",$E11=""),"Hallazgo sin destino",IF($D11="","Sin requisito, justificado","Deriva requisito"))) -> Deriva requisito
A12: H-08 | B12: El cliente valora inmediatez y anonimato: sin formularios de filiación y con cobro en un solo paso. | C12: AE1 · II.5 (sociocultural) | D12: RNF-02, RNF-03, RNF-08 | F12: =IF($A12="","",IF(AND($D12="",$E12=""),"Hallazgo sin destino",IF($D12="","Sin requisito, justificado","Deriva requisito"))) -> Deriva requisito
A13: H-09 | B13: Hay intermitencias de energía e internet: el cronómetro debe vivir en el servidor y el navegador recupera el estado al reconectar. | C13: AE1 · II.5 (tecnológico) | D13: RNF-06, RNF-09 | F13: =IF($A13="","",IF(AND($D13="",$E13=""),"Hallazgo sin destino",IF($D13="","Sin requisito, justificado","Deriva requisito"))) -> Deriva requisito
A14: H-10 | B14: Riesgo de resistencia del personal de conserjería a perder el control manual de la recaudación. | C14: AE1 · II.5 (FODA, amenaza) | E14: Riesgo de adopción: se gestiona con la capacitación (X.5) y con la usabilidad de RNF-05; no genera un requisito propio. | F14: =IF($A14="","",IF(AND($D14="",$E14=""),"Hallazgo sin destino",IF($D14="","Sin requisito, justificado","Deriva requisito"))) -> Sin requisito, justificado
A15: H-11 | B15: El personal de maestranza y limpieza queda fuera del relevamiento; los tiempos de limpieza son estimaciones indirectas de conserjería. | C15: AE1 · II.2 y II.6 (limitaciones) | D15: RF-12 | F15: =IF($A15="","",IF(AND($D15="",$E15=""),"Hallazgo sin destino",IF($D15="","Sin requisito, justificado","Deriva requisito"))) -> Deriva requisito
A16: H-12 | B16: Exclusiones del alcance de la AE1: liquidación de haberes (gestión contable externa) e interfaz de reservas para clientes (anonimato). | C16: AE1 · 1.6 | E16: Exclusiones de alcance (III.4): nómina e interfaz de reservas quedan fuera del proyecto. | F16: =IF($A16="","",IF(AND($D16="",$E16=""),"Hallazgo sin destino",IF($D16="","Sin requisito, justificado","Deriva requisito"))) -> Sin requisito, justificado
A17: H-13 | B17: El personal de conserjería cumple tres guardias fijas de 8 h: 06:00, 14:00 y 22:00. | C17: Entrevista · pág. 1 | D17: RF-08, RF-14 | F17: =IF($A17="","",IF(AND($D17="",$E17=""),"Hallazgo sin destino",IF($D17="","Sin requisito, justificado","Deriva requisito"))) -> Deriva requisito
A18: H-14 | B18: Volumen informado por la gerencia: unos 30 turnos por día entre semana y unos 40 los fines de semana. | C18: Entrevista · pág. 1 | D18: RNF-02 | F18: =IF($A18="","",IF(AND($D18="",$E18=""),"Hallazgo sin destino",IF($D18="","Sin requisito, justificado","Deriva requisito"))) -> Deriva requisito
A19: H-15 | B19: El estado de cada habitación se lleva con papeles anotadores individuales; la limpieza no se anota. | C19: Entrevista · pág. 1 | D19: RF-01, RF-07, RF-12 | F19: =IF($A19="","",IF(AND($D19="",$E19=""),"Hallazgo sin destino",IF($D19="","Sin requisito, justificado","Deriva requisito"))) -> Deriva requisito
A20: H-16 | B20: Cada anotador registra habitación, hora de entrada y de salida, consumos y patente del vehículo (o «peatón»); cada guardia recibe 20 anotadores. | C20: Entrevista · pág. 1 | D20: RF-02, RF-03, RF-04, RF-05, RNF-08 | F20: =IF($A20="","",IF(AND($D20="",$E20=""),"Hallazgo sin destino",IF($D20="","Sin requisito, justificado","Deriva requisito"))) -> Deriva requisito
A21: H-17 | B21: En el recambio, el conserje suma sus anotadores; el total debe coincidir con el efectivo de la gaveta más los pagos digitales, y se devuelven los 20 anotadores. | C21: Entrevista · pág. 2 | D21: RF-06, RF-08, RF-14, RNF-04 | F21: =IF($A21="","",IF(AND($D21="",$E21=""),"Hallazgo sin destino",IF($D21="","Sin requisito, justificado","Deriva requisito"))) -> Deriva requisito
A22: H-18 | B22: Un faltante se descuenta de la caja de la guardia que cierra y se computa como faltante a auditar por los encargados. | C22: Entrevista · pág. 2 | D22: RF-08, RF-09 | F22: =IF($A22="","",IF(AND($D22="",$E22=""),"Hallazgo sin destino",IF($D22="","Sin requisito, justificado","Deriva requisito"))) -> Deriva requisito
A23: H-19 | B23: Los pagos digitales generan un comprobante del POSNET que se suma en el arqueo; hay un QR en las habitaciones. | C23: Entrevista · pág. 2 | D23: RF-06 | F23: =IF($A23="","",IF(AND($D23="",$E23=""),"Hallazgo sin destino",IF($D23="","Sin requisito, justificado","Deriva requisito"))) -> Deriva requisito
A24: H-20 | B24: Los papeles con datos de los huéspedes se archivan físicamente en un depósito bajo llave dentro del establecimiento. | C24: Entrevista · pág. 2 | D24: RNF-03, RNF-08 | F24: =IF($A24="","",IF(AND($D24="",$E24=""),"Hallazgo sin destino",IF($D24="","Sin requisito, justificado","Deriva requisito"))) -> Deriva requisito
A25: H-21 | B25: El motel trabaja bajo las ordenanzas municipales, con habilitación para alojamiento por hora y venta de bebidas alcohólicas las 24 h, y atiende solo a mayores de 18 años. | C25: Entrevista · pág. 2 | E25: Contexto normativo del entorno (III.1): el motel ya cumple las ordenanzas; no exige funcionalidad al sistema. | F25: =IF($A25="","",IF(AND($D25="",$E25=""),"Hallazgo sin destino",IF($D25="","Sin requisito, justificado","Deriva requisito"))) -> Sin requisito, justificado
A26: H-22 | B26: Los anotadores se cambian por montos menores o se entregan en blanco; la gerencia detecta estas maniobras varias veces al mes. | C26: Entrevista · pág. 2 | D26: RF-08, RNF-01 | F26: =IF($A26="","",IF(AND($D26="",$E26=""),"Hallazgo sin destino",IF($D26="","Sin requisito, justificado","Deriva requisito"))) -> Deriva requisito
A27: H-23 | B27: Auditar un balance hacia atrás exige horas de revisión manual, turno por turno. | C27: Entrevista · pág. 3 | D27: RF-10, RNF-01 | F27: =IF($A27="","",IF(AND($D27="",$E27=""),"Hallazgo sin destino",IF($D27="","Sin requisito, justificado","Deriva requisito"))) -> Deriva requisito
A28: H-24 | B28: La gerencia espera controlar todo el movimiento de clientes y consumos y confía en que el personal se adapte al sistema digital. | C28: Entrevista · pág. 3 | E28: Expectativa de la gerencia: sustenta el criterio de éxito (TPA ≤ 5 min), no un requisito. | F28: =IF($A28="","",IF(AND($D28="",$E28=""),"Hallazgo sin destino",IF($D28="","Sin requisito, justificado","Deriva requisito"))) -> Sin requisito, justificado
F29: =IF($A29="","",IF(AND($D29="",$E29=""),"Hallazgo sin destino",IF($D29="","Sin requisito, justificado","Deriva requisito")))
F30: =IF($A30="","",IF(AND($D30="",$E30=""),"Hallazgo sin destino",IF($D30="","Sin requisito, justificado","Deriva requisito")))
F31: =IF($A31="","",IF(AND($D31="",$E31=""),"Hallazgo sin destino",IF($D31="","Sin requisito, justificado","Deriva requisito")))
F32: =IF($A32="","",IF(AND($D32="",$E32=""),"Hallazgo sin destino",IF($D32="","Sin requisito, justificado","Deriva requisito")))
F33: =IF($A33="","",IF(AND($D33="",$E33=""),"Hallazgo sin destino",IF($D33="","Sin requisito, justificado","Deriva requisito")))
F34: =IF($A34="","",IF(AND($D34="",$E34=""),"Hallazgo sin destino",IF($D34="","Sin requisito, justificado","Deriva requisito")))
F35: =IF($A35="","",IF(AND($D35="",$E35=""),"Hallazgo sin destino",IF($D35="","Sin requisito, justificado","Deriva requisito")))
F36: =IF($A36="","",IF(AND($D36="",$E36=""),"Hallazgo sin destino",IF($D36="","Sin requisito, justificado","Deriva requisito")))
F37: =IF($A37="","",IF(AND($D37="",$E37=""),"Hallazgo sin destino",IF($D37="","Sin requisito, justificado","Deriva requisito")))
F38: =IF($A38="","",IF(AND($D38="",$E38=""),"Hallazgo sin destino",IF($D38="","Sin requisito, justificado","Deriva requisito")))
F39: =IF($A39="","",IF(AND($D39="",$E39=""),"Hallazgo sin destino",IF($D39="","Sin requisito, justificado","Deriva requisito")))
F40: =IF($A40="","",IF(AND($D40="",$E40=""),"Hallazgo sin destino",IF($D40="","Sin requisito, justificado","Deriva requisito")))
... F61: =IF($A61="","",IF(AND($D61="",$E61=""),"Hallazgo sin destino",IF($D61="","Sin requisito, justificado","Deriva requisito")))

Sheet Entidades
A1: Lista filtrada de entidades del dominio · Instrumento 28
A2: Cada candidata pasa por el filtro de las tres preguntas. Las descartadas no se borran: se reclasifican, porque los descartes de hoy son las preguntas del glosario de mañana.
A4: Candidata (sustantivo de la organización) | B4: ¿Identidad propia? | C4: ¿Datos y reglas propios? | D4: ¿Dentro del recorte? | E4: Veredicto | F4: Fuente que la acredita | G4: Relaciones principales
A5: Habitación | B5: Sí | C5: Sí | D5: Sí | E5: Entidad | F5: H-01, H-15 | G5: Una habitación acumula muchos turnos; en un instante tiene como máximo un turno En Curso.
A6: Turno | B6: Sí | C6: Sí | D6: Sí | E6: Entidad | F6: H-16 | G6: Pertenece a una habitación y a la guardia que lo abre; copia los importes de la tarifa vigente; agrupa consumos y pagos.
A7: Tarifa | B7: Sí | C7: Sí | D7: Sí | E7: Entidad | F7: H-07 | G7: Una tarifa rige para muchos turnos; el turno copia sus importes al abrirse, de modo que un cambio no altera turnos liquidados.
A8: Artículo | B8: Sí | C8: Sí | D8: Sí | E8: Entidad | F8: H-05, H-16 | G8: Tiene stock y precio; se asocia a muchas líneas de consumo.
A9: Detalle_Consumo | B9: Sí | C9: Sí | D9: Sí | E9: Entidad | F9: H-16 | G9: Pertenece a un turno En Curso y referencia un artículo; descuenta stock en la misma transacción.
A10: Pago | B10: Sí | C10: Sí | D10: Sí | E10: Entidad | F10: H-17, H-19 | G10: Pertenece a un turno; lo registra un operador en una guardia; un turno admite varios pagos (efectivo y comprobantes).
A11: Operador (conserje) | B11: Sí | C11: Sí | D11: Sí | E11: Entidad | F11: H-06, H-13, H-17 | G11: Hay un solo responsable por guardia, y todas las operaciones de la guardia van a su nombre (acta del 19/10/2026); registra turnos, pagos y arqueos; a él se atribuye un faltante.
A12: Guardia | B12: Sí | C12: Sí | D12: Sí | E12: Entidad | F12: H-13 | G12: Franja de 8 h (06:00, 14:00 o 22:00) con un operador responsable; recibe un fondo de cambio de $25.000 y agrupa los pagos que se registran en ella (acta del 19/10/2026).
A13: Arqueo_Caja | B13: Sí | C13: Sí | D13: Sí | E13: Entidad | F13: H-17, H-18 | G13: Uno por guardia: total declarado (efectivo como monto total), total del sistema y diferencia; inmutable al confirmarse. Si el conserje deja la caja abierta, lo confirma la gerencia con un motivo (RF-14).
A14: Patente | B14: No | C14: No | D14: Sí | E14: Atributo de otra entidad | F14: H-16, H-20 | G14: Se guarda en la estadía activa, separada del registro financiero, y se elimina dentro de las 24 h posteriores al cierre (RNF-08).
A15: Cliente | B15: No | C15: No | D15: No | E15: Elemento del entorno | F15: H-08, H-16 | G15: Lo padece el sistema: solo existe como tipo (Auto, Moto, Peatón) y patente opcional; no se registran datos filiatorios.
... A17: Diferencia de caja | B17: No | C17: No | D17: Sí | E17: Atributo de otra entidad | F17: H-18 | G17: Atributo calculado de Arqueo_Caja: total declarado − total del sistema.

Sheet Reglas
A1: Registro de reglas de negocio · Instrumento 29
A2: Regla y requisito derivado deben citar la misma fuente: esa coincidencia es la trazabilidad que la dimensión 1 de la rúbrica verifica.
A4: Código | B4: Tipo | C4: Enunciado verificable | D4: Fuente | E4: Estado | F4: Requisito derivado (ID)
A5: RN-RES-01 | B5: Restricción | C5: Un turno FINALIZADO o Anulado no admite nuevos consumos, cambio de habitación ni modificación de importes, y no se puede borrar; lo mismo rige para sus pagos y consumos. | D5: H-04, H-22 · Acta 23/09 (RNF-01) | E5: Validada | F5: RF-02, RNF-01
A6: RN-RES-02 | B6: Restricción | C6: Confirmado el cierre de caja de una guardia, el arqueo no admite UPDATE ni DELETE. | D6: H-04, H-18 · Acta 23/09 (RF-08, RF-09, RNF-01) | E6: Validada | F6: RF-08, RNF-01
A7: RN-RES-03 | B7: Restricción | C7: Ni la interfaz ni la API muestran al operador el total del sistema de la guardia antes de que confirme el recuento físico. | D7: H-06 · Acta 23/09 (RF-08) | E7: Validada | F7: RF-08
A8: RN-RES-04 | B8: Restricción | C8: La patente de un turno se elimina dentro de las 24 h posteriores a su cierre. | D8: H-16, H-20 | E8: Validada | F8: RNF-08
A9: RN-DER-01 | B9: Derivación | C9: Si la estadía supera los 120 min, se suma $2.500 por cada fracción de 30 min o porción de excedente; no se aplica tolerancia. | D9: H-05, H-07 · Acta 23/09 (RF-03) | E9: Validada | F9: RF-03
A10: RN-DER-02 | B10: Derivación | C10: El total adeudado del turno es la tarifa base, más el sobreturno de RN-DER-01, más la suma de los subtotales de consumo. | D10: H-16, H-17 · Acta 23/09 (RF-03, RF-04) | E10: Validada | F10: RF-03, RF-04
A11: RN-DER-03 | B11: Derivación | C11: Diferencia = total declarado (efectivo + comprobantes) − total del sistema. Si es 0 es «Correcto»; si es negativa, «Faltante»; si es positiva, «Sobrante». | D11: H-17, H-18 · Acta 23/09 (RF-09) | E11: Validada | F11: RF-09
A12: RN-DER-04 | B12: Derivación | C12: El cobro se imputa a la caja del conserje que lo confirma, aunque el turno lo haya abierto otro conserje u otra guardia. Un turno abierto a las 21:30 por la guardia de las 14:00 y cobrado a las 23:30 entra a la caja de la guardia de las 22:00. | D12: H-13, H-17 · Acta 19/10 | E12: Validada | F12: RF-08
A13: RN-EXI-01 | B13: Existencia | C13: Solo se abre un turno en una habitación que está en estado Libre. | D13: H-15 · Acta 23/09 (RF-01, RF-02) | E13: Validada | F13: RF-01, RF-02
A14: RN-EXI-02 | B14: Existencia | C14: Un consumo se registra solo si el stock del artículo es mayor o igual a la cantidad pedida, y el stock se descuenta en la misma transacción. | D14: H-05 · Acta 23/09 (RF-04, RF-05) | E14: Validada | F14: RF-04, RF-05
A15: RN-EXI-03 | B15: Existencia | C15: Una habitación pasa a En Limpieza solo si su turno queda FINALIZADO con un saldo adeudado de exactamente $0. | D15: H-15 · Acta 23/09 (RF-06, RF-07) | E15: Validada | F15: RF-06, RF-07
... A17: RN-RES-05 | B17: Restricción | C17: Un arqueo que confirma la gerencia en lugar del conserje (cierre supervisado) exige un motivo y registra quién lo confirmó; la caja sigue siendo del conserje. | D17: H-13 · Acta 19/10 (punto 9) | E17: Validada | F17: RF-14
A18: R-14
A19: R-15
A20: R-16
A21: R-17
A22: R-18
A23: R-19
A24: R-20
A25: R-21
A26: R-22
A27: R-23
A28: R-24
A29: R-25
... A40: R-36

Sheet Glosario
A1: Glosario del dominio · Instrumento 30
A2: Vocabulario normativo del informe completo y, más adelante, de las tablas del sistema. La entrada más valiosa es la del término en disputa: el que dos personas de la organización usan distinto.
A4: Término (como lo usa la organización) | B4: Definición operativa (una o dos oraciones) | C4: Sinónimos y falsos amigos detectados | D4: Fuente (quién lo usa así) | E4: ¿En disputa?
A5: Turno (de alojamiento) | B5: Ocupación de una habitación por una estadía base de 120 min más sobreturnos. | C5: Falso amigo: «turno» de guardia. La entrevista llama «turnos» tanto a las estadías («treinta turnos por día») como a las jornadas del personal. | D5: Entrevista · pág. 1 | E5: Sí
A6: Guardia (turno de guardia) | B6: Jornada de 8 h de un operador: 06:00, 14:00 o 22:00. Al terminar se hace el recambio y el arqueo. | C6: Falso amigo: turno de alojamiento. El relevo se llama «cambio de turno». | D6: Entrevista · pág. 1 y 2 | E6: Sí
A7: Sobreturno | B7: Tiempo que excede los 120 min de la estadía base, cobrado por fracciones de 30 min o porción. | C7: Sin sinónimos relevados. | D7: AE1 · II.5 | E7: No
A8: Cierre ciego | B8: Rendición en la que el operador declara el efectivo y los comprobantes sin ver el total del sistema. | C8: Sin sinónimos relevados. | D8: AE1 · II.5 | E8: No
A9: Recambio de guardia | B9: Momento en que una guardia termina y la siguiente recibe la caja y los anotadores. | C9: «Cambio de turno» (entrevista). | D9: Entrevista · pág. 2 | E9: No
A10: Papel anotador | B10: Hoja individual donde se anota habitación, horas, consumos y patente de cada estadía. | C10: «Ficha de papel» de 10 × 10 cm (AE1). | D10: Entrevista · pág. 1; AE1 · 1.1 | E10: No
A11: Minibar | B11: Productos de consumo que se despachan a pedido a la habitación y se anotan en el papel. | C11: Falso amigo: «heladera de habitación» (a confirmar con la gerencia). | D11: Entrevista · pág. 1 | E11: Sí
A12: Estadía activa | B12: Período en el que el vehículo está dentro del motel; es el único momento en que se necesita la patente. | C12: Sin sinónimos relevados. | D12: Propuesta del autor (RNF-08), a validar | E12: Sí
A13: Operador (conserje) | B13: Persona que atiende la ventanilla durante una guardia y rinde su caja. | C13: «Conserje» (entrevista). | D13: Entrevista · pág. 1 | E13: No
A14: TDC (Tasa de Discrepancia de Caja) | B14: Proporción de recambios cuya liquidación presenta faltante o sobrante: 1 de cada 10 (10 %). Es una frecuencia, no un monto de dinero. | C14: «Descuadre». | D14: AE1 · II.3 | E14: No
A15: TPA (Tiempo Promedio de Arqueo) | B15: Minutos que demora el arqueo de un recambio: 17 min en la línea de base. | C15: Sin sinónimos relevados. | D15: AE1 · II.3 | E15: No
A16: Fondo de cambio | B16: Efectivo que recibe la caja al empezar la guardia para dar vuelto: $25.000. Se cuenta junto con lo cobrado en el arqueo. | C16: «Cambio», «fondo fijo». | D16: Gerencia · acta del 19/10/2026 | E16: No

Sheet Iteraciones
A1: Plan de iteraciones y presupuesto de horas · Capítulo V
A2: El cronograma se construye sobre el presupuesto efectivo de horas-persona y se alinea con la cadencia de artefactos: v1 en la semana 8, v2 en la semana 11, v3 en la semana 13 y versión funcional congelada en la semana 14.
A4: Iteración | B4: Desde | C4: Hasta | D4: Objetivo verificable | E4: Requisitos comprometidos (ID) | F4: Entregable de cierre | G4: Horas asignadas
A5: 1 | B5: 13/08/2026 | C5: 03/09/2026 | D5: Relevar la organización, medir la línea de base (TPA 17 min, TDC 10 %) y validar la maqueta v0 con la gerencia el 29/08. | E5: H-01 a H-24 (hallazgos); sin requisitos comprometidos | F5: Prototipo v0: maqueta navegable en Figma e informe de la AE1. | G5: =SUMIF($C$32:$C$59,A5,$H$32:$H$59) -> 48
A6: 2 | B6: 07/09/2026 | C6: 02/10/2026 | D6: Delimitar el dominio, formalizar el catálogo y construir el esqueleto ejecutable (Walking Skeleton) con canal de integración continua. | E6: RF-01 a RF-07, RNF-01, RNF-03, RNF-05 (10 Must) | F6: Prototipo v1 (etiqueta v1.1): apertura, consumo, cobro, retorno a Limpieza e inmutabilidad. | G6: =SUMIF($C$32:$C$59,A6,$H$32:$H$59) -> 44
A7: 3 | B7: 05/10/2026 | C7: 29/10/2026 | D7: Implementar el cierre de caja ciego con Operador, Guardia y Arqueo; la autenticación; la retención de la patente y la separación de roles de base de datos. | E7: RF-08, RF-09, RNF-02, RNF-04, RNF-08 (5 Must), RNF-07 y RF-14 (Should, acta del 19/10/2026) | F7: Prototipo v2: cierre ciego con pruebas automáticas. La retención de la patente (RNF-08) y el rol de aplicación se adelantan a la v1.2 (05/10/2026). | G7: =SUMIF($C$32:$C$59,A7,$H$32:$H$59) -> 40
A8: 4 | B8: 02/11/2026 | C8: 26/11/2026 | D8: Completar reportes, edición de tarifas y alertas; desplegar en la nube y congelar la versión demostrable. | E8: RF-10, RF-11, RF-12, RNF-06, RNF-09 (Should y Could) | F8: Prototipo v3: versión congelada y desplegada, demostrable ante tribunal. | G8: =SUMIF($C$32:$C$59,A8,$H$32:$H$59) -> 44
A9: 5
A10: 6
A11: 7
A12: 8
A15: Presupuesto de horas-persona
A16: Integrantes del equipo | B16: 1
A17: Horas semanales reales por integrante (declaradas, no deseadas) | B17: 12
A18: Semanas del período | B18: 16
A19: Presupuesto total | B19: =IF(COUNT(B16:B18)=3,B16*B17*B18,"") -> 192
A20: Reducción prevista por exámenes y feriados (horas) | B20: 16 | C20: 24 h de reserva por exámenes y contingencias (2 semanas) menos 8 h adicionales de las semanas 7, 8, 13 y 14 a 14 h
A21: Presupuesto efectivo resultante | B21: =IF(B19="","",B19-N(B20)) -> 176
A22: Horas ya asignadas a iteraciones | B22: =SUM(G5:G12) -> 176
A23: Margen disponible | B23: =IF(B21="","",B21-B22) -> 0
A25: Cláusula de contingencia (exigencia vii de la consigna)
A26: Si el presupuesto de horas cae un tercio, se posterga | B26: Con la pérdida de un tercio (59 h) quedan 25 h de las 84 por ejecutar al iniciar la iteración 3. Postergar RF-10, RF-11 y RF-12 libera solo 12 h y no alcanza; caben RF-08 y RF-09 (17 h), sus pruebas de aceptación (3 h) y RNF-08 (5 h). RNF-02, RNF-04, RNF-07 y la iteración 4 pasan a trabajo futuro y el PMV queda con 13 de los 15 Must.
A27: Criterio de redistribución, según el acta de constitución | B27: Autoría individual (Thiago Leal): no hay redistribución entre integrantes; el esfuerzo restante se concentra en RF-08, RF-09 y RNF-08 sobre el esqueleto ya construido.
A28: Qué no se sacrifica en ningún caso | B28: La trazabilidad del catálogo, la bitácora y la ejecutabilidad del prototipo (v1.2): son condiciones de cómputo.
A30: Plan de horas por requisito y perfil (apoya las horas asignadas y el Capítulo X)
A31: Tarea o requisito | B31: Descripción | C31: Iteración | D31: Prioridad | E31: Backend (h) | F31: Frontend (h) | G31: Analista y QA (h) | H31: Total (h)
A32: T-REL | B32: Relevamiento, análisis y redacción de la AE1 | C32: 1 | D32: Transversal | E32: 0 | F32: 0 | G32: 36 | H32: =SUM(E32:G32) -> 36
A33: T-MAQ | B33: Maqueta navegable v0 en Figma | C33: 1 | D33: Transversal | E33: 0 | F33: 12 | G33: 0 | H33: =SUM(E33:G33) -> 12
A34: RF-01 | B34: Grilla de habitaciones | C34: 2 | D34: Must | E34: 0 | F34: 6 | G34: 0 | H34: =SUM(E34:G34) -> 6
A35: RF-02 | B35: Apertura de turno | C35: 2 | D35: Must | E35: 3 | F35: 2 | G35: 0 | H35: =SUM(E35:G35) -> 5
A36: RF-03 | B36: Liquidación con sobreturno | C36: 2 | D36: Must | E36: 5 | F36: 0 | G36: 0 | H36: =SUM(E36:G36) -> 5
A37: RF-04 | B37: Consumo de minibar | C37: 2 | D37: Must | E37: 3 | F37: 1 | G37: 0 | H37: =SUM(E37:G37) -> 4
A38: RF-05 | B38: Rechazo por stock insuficiente | C38: 2 | D38: Must | E38: 1 | F38: 1 | G38: 0 | H38: =SUM(E38:G38) -> 2
A39: RF-06 | B39: Cobro desglosado y constancia | C39: 2 | D39: Must | E39: 3 | F39: 2 | G39: 0 | H39: =SUM(E39:G39) -> 5
A40: RF-07 | B40: Rechazo de limpieza con deuda | C40: 2 | D40: Must | E40: 1 | F40: 1 | G40: 0 | H40: =SUM(E40:G40) -> 2
A41: RNF-01 | B41: Triggers de inmutabilidad | C41: 2 | D41: Must | E41: 5 | F41: 0 | G41: 0 | H41: =SUM(E41:G41) -> 5
A42: RNF-03 | B42: Sin datos filiatorios | C42: 2 | D42: Must | E42: 1 | F42: 0 | G42: 0 | H42: =SUM(E42:G42) -> 1
A43: RNF-05 | B43: Resolución 1366 × 768 y controles de 44 px | C43: 2 | D43: Must | E43: 0 | F43: 2 | G43: 0 | H43: =SUM(E43:G43) -> 2
... A59: T-CAP | B59: Capacitación al personal (3 jornadas de 2 h) | C59: 4 | D59: Transversal | E59: 0 | F59: 0 | G59: 6 | H59: =SUM(E59:G59) -> 6
A60: Total | E60: =SUM(E32:E59) -> 71 | F60: =SUM(F32:F59) -> 42 | G60: =SUM(G32:G59) -> 63 | H60: =SUM(H32:H59) -> 176

Sheet Recursos
A1: Dimensionamiento de recursos · Capítulo X
A2: Cada asignación con su justificación y su fuente. Toda cifra de costo responde las tres preguntas: quién la produjo, con qué método y sobre qué universo, y para qué período de referencia. No se promedian cifras de universos distintos.
A4: Clase | B4: Concepto | C4: Cantidad | D4: Unidad | E4: Costo unitario | F4: Subtotal | G4: Fuente, período y justificación
A5: Humanos | B5: Perfil Backend (Thiago Leal) | C5: =Iteraciones!E60 -> 71 | D5: hora | E5: 21565 | F5: =IF(OR($C5="",$E5=""),"",$C5*$E5) -> 1531115 | G5: OPSSI-CESSI, salarios brutos del sector SSI, promedio de marzo de 2026 (T1-2026), según CESSI/OPSSI vía Mercado (2026).3,738,000 ÷ 173,33 h (jornada de 40 h) = 21,565 por hora, redondeado a la unidad. Salario bruto: no incluye contribuciones patronales.
A6: Humanos | B6: Perfil Frontend (Thiago Leal) | C6: =Iteraciones!F60 -> 42 | D6: hora | E6: 21565 | F6: =IF(OR($C6="",$E6=""),"",$C6*$E6) -> 905730 | G6: Misma tarifa: una sola persona ejecuta los tres perfiles.
A7: Humanos | B7: Perfil Analista y QA (Thiago Leal) | C7: =Iteraciones!G60 -> 63 | D7: hora | E7: 21565 | F7: =IF(OR($C7="",$E7=""),"",$C7*$E7) -> 1358595 | G7: Misma tarifa.
A8: Físicos y materiales | B8: Terminal de la ventanilla (PC del motel) | C8: 1 | D8: equipo | E8: 0 | F8: =IF(OR($C8="",$E8=""),"",$C8*$E8) -> 0 | G8: Equipo del motel; sin costo para el proyecto. Monitor de 1366 × 768 px, relevado por el autor (RNF-05).
A9: Físicos y materiales | B9: Terminal POSNET | C9: 1 | D9: dispositivo | E9: 0 | F9: =IF(OR($C9="",$E9=""),"",$C9*$E9) -> 0 | G9: Equipo del motel (entrevista del 29/08, pág. 2); sin costo para el proyecto.
A10: Financieros | B10: Aprovisionamiento inicial del entorno en la nube | C10: 1 | D10: servicio | E10: 120000 | F10: =IF(OR($C10="",$E10=""),"",$C10*$E10) -> 120000 | G10: Estimación del autor, sin cotización: configuración del entorno de producción, dominio y certificado.
A11: Financieros | B11: Capacitación al personal (3 jornadas de 2 h) | C11: 3 | D11: jornada | E11: 40000 | F11: =IF(OR($C11="",$E11=""),"",$C11*$E11) -> 120000 | G11: Estimación del autor: 3 jornadas presenciales para los conserjes y el administrador.
A12: Tecnológicos | B12: Instancia AWS EC2 t4g.small | C12: 12 | D12: mes | E12: 30129 | F12: =IF(OR($C12="",$E12=""),"",$C12*$E12) -> 361548 | G12: AWS EC2 on-demand, Linux, São Paulo (sa-east-1): USD 0,0268 por hora × 730 h = USD 19,56 por mes, a $1.540 por USD (se verifica al contratar).
A13: Tecnológicos | B13: Copias de seguridad cifradas en AWS S3 | C13: 12 | D13: mes | E13: 1540 | F13: =IF(OR($C13="",$E13=""),"",$C13*$E13) -> 18480 | G13: Estimación del autor: USD 1 por mes a $1.540 por USD (se verifica al contratar).
A14: Tecnológicos | B14: Dominio | C14: 1 | D14: año | E14: 9500 | F14: =IF(OR($C14="",$E14=""),"",$C14*$E14) -> 9500 | G14: Estimación del autor, sin cotización (registro de dominio).
A15: Otros | B15: Soporte preventivo y correctivo posterior al despliegue | C15: 12 | D15: mes | E15: 20000 | F15: =IF(OR($C15="",$E15=""),"",$C15*$E15) -> 240000 | G15: Estimación del autor: 2 h mensuales de guardia posteriores al despliegue.
F16: =IF(OR($C16="",$E16=""),"",$C16*$E16)
F17: =IF(OR($C17="",$E17=""),"",$C17*$E17)
F18: =IF(OR($C18="",$E18=""),"",$C18*$E18)
F19: =IF(OR($C19="",$E19=""),"",$C19*$E19)
F20: =IF(OR($C20="",$E20=""),"",$C20*$E20)
F21: =IF(OR($C21="",$E21=""),"",$C21*$E21)
F22: =IF(OR($C22="",$E22=""),"",$C22*$E22)
F23: =IF(OR($C23="",$E23=""),"",$C23*$E23)
F24: =IF(OR($C24="",$E24=""),"",$C24*$E24)
F25: =IF(OR($C25="",$E25=""),"",$C25*$E25)
F26: =IF(OR($C26="",$E26=""),"",$C26*$E26)
F27: =IF(OR($C27="",$E27=""),"",$C27*$E27)
... F34: =IF(OR($C34="",$E34=""),"",$C34*$E34)
E36: Total general | F36: =SUM(F5:F34) -> 4664968
E37: Horas humanas comprometidas | F37: =SUMIF($A$5:$A$34,"Humanos",$C$5:$C$34) -> 176
E38: Coherencia con el Capítulo V | F38: =IF(Iteraciones!$B$21="","Falta el presupuesto efectivo",IF(F37=Iteraciones!$B$21,"Coherente",IF(F37>Iteraciones!$B$21,"Excede el presupuesto","No agota el presupuesto: revisar"))) -> Coherente

Sheet Panel
A1: Panel de control de la entrega
A2: Los valores se calculan solos a partir de las demás hojas. Ninguna celda de esta hoja se escribe a mano. Recórrala la noche anterior a la entrega: cada línea en rojo es una observación previsible en la devolución.
A4: Indicador | B4: Valor | C4: Qué debe verificarse
A5: Requisitos registrados | B5: =COUNTIF(Catálogo!$A$5:$A$201,"?*") -> 23 | C5: Un catálogo de menos de ocho requisitos rara vez cubre el alcance declarado.
A6: Requisitos con criterio de aceptación | B6: =COUNTIFS(Catálogo!$A$5:$A$201,"?*",Catálogo!$G$5:$G$201,"?*") -> 23 | C6: Debe coincidir con el total. Un requisito sin criterio no se computa.
A7: Requisitos trazados a un hallazgo o acta | B7: =COUNTIFS(Catálogo!$A$5:$A$201,"?*",Catálogo!$H$5:$H$201,"?*") -> 23 | C7: Debe coincidir con el total. Sin origen, el requisito no ingresa al catálogo.
A8: Requisitos no funcionales | B8: =COUNTIFS(Catálogo!$A$5:$A$201,"?*",Catálogo!$C$5:$C$201,"No funcional") -> 9 | C8: Un catálogo sin requisitos no funcionales no decidió arquitectura.
A9: No funcionales sin categoría declarada | B9: =COUNTIFS(Catálogo!$C$5:$C$201,"No funcional",Catálogo!$D$5:$D$201,"") -> 0 | C9: Debe ser cero.
A10: Requisitos «Must» | B10: =COUNTIFS(Catálogo!$A$5:$A$201,"?*",Catálogo!$E$5:$E$201,"Must") -> 15 | C10: Priorizar es nombrar lo que no se hará. Si casi todo es «Must», no se priorizó.
A11: Requisitos declarados dentro del MVP | B11: =COUNTIFS(Catálogo!$A$5:$A$201,"?*",Catálogo!$K$5:$K$201,"Sí") -> 15 | C11: Debe coincidir con la cantidad de «Must».
A12: Coherencia entre «Must» y producto mínimo viable | B12: =IF(COUNTIFS(Catálogo!$A$5:$A$201,"?*",Catálogo!$E$5:$E$201,"Must")=COUNTIFS(Catálogo!$A$5:$A$201,"?*",Catálogo!$K$5:$K$201,"Sí"),"Coherente","REVISAR") -> Coherente | C12: Si dice REVISAR, uno de los dos apartados está mal escrito: el catálogo o el V.5.
A13: Requisitos validados con el referente | B13: =COUNTIFS(Catálogo!$A$5:$A$201,"?*",Catálogo!$I$5:$I$201,"Validado") -> 23 | C13: Un requisito redactado y no validado carece de valor probatorio.
A14: Filas del catálogo con campos faltantes | B14: =COUNTIF(Catálogo!$L$5:$L$201,"Faltan campos")+COUNTIF(Catálogo!$L$5:$L$201,"Falta categoría")+COUNTIF(Catálogo!$L$5:$L$201,"Falta definir si integra el MVP") -> 0 | C14: Debe ser cero antes de exportar el PDF.
A15: Hallazgos de la AE1 registrados | B15: =COUNTIF(Trazabilidad!$A$5:$A$61,"?*") -> 24 | C15: Todo hallazgo del Capítulo II que sostuvo el diagnóstico debería estar.
A16: Hallazgos sin requisito ni justificación | B16: =COUNTIF(Trazabilidad!$F$5:$F$61,"Hallazgo sin destino") -> 0 | C16: Debe ser cero. El silencio no es una decisión.
A17: Entidades aceptadas en el modelo del dominio | B17: =COUNTIF(Entidades!$E$5:$E$45,"Entidad") -> 9 | C17: Cada una debe tener su fuente en la columna correspondiente.
A18: Candidatas evaluadas y reclasificadas | B18: =COUNTIF(Entidades!$A$5:$A$45,"?*")-COUNTIF(Entidades!$E$5:$E$45,"Entidad") -> 4 | C18: Los descartes documentados son los que permiten defender la delimitación.
A19: Reglas de negocio registradas | B19: =COUNTIF(Reglas!$C$5:$C$40,"?*") -> 13 | C19: Mínimo exigido en el taller de la Clase 8: tres reglas enunciadas de modo verificable.
